<?xml version="1.0" ?>
<!-- =================================================================================== -->
<!-- |    This document was autogenerated by xacro from src/barrett_hand_sim_dart/scenes/pinch.urdf.xacro | -->
<!-- |    EDITING THIS FILE BY HAND IS NOT RECOMMENDED                                 | -->
<!-- =================================================================================== -->
<robot name="velma" xmlns:controller="http://playerstage.sourceforge.net/gazebo/xmlschema/#controller" xmlns:geom="http://playerstage.sourceforge.net/gazebo/xmlschema/#geom" xmlns:interface="http://playerstage.sourceforge.net/gazebo/xmlschema/#interface" xmlns:sensor="http://playerstage.sourceforge.net/gazebo/xmlschema/#sensor" xmlns:xacro="http://www.ros.org/wiki/xacro">
  <material name="DarkGrey">
    <color rgba="0.3 0.3 0.3 1.0"/>
  </material>
  <material name="Red">
    <color rgba="0.3 0.3 0.3 1.0"/>
  </material>
  <material name="Black">
    <color rgba="0 0 0 1.0"/>
  </material>
  <material name="Orange">
    <color rgba="1.0 0.487 0 1.0"/>
  </material>
  <material name="Silver">
    <color rgba="1.0 1.0 1.0 1.0"/>
  </material>
  <material name="Grey">
    <color rgba="0.7 0.7 0.7 1.0"/>
  </material>
  <material name="Blue">
    <color rgba="0.0 0.0 0.8 1.0"/>
  </material>
  <material name="HandGray">
    <color rgba="0.953 0.996 0.694 1.0"/>
  </material>
  <material name="SickBlue">
    <color rgba="0.3058 0.5921 0.7294 1.0"/>
  </material>
  <link name="world"/>
  <!-- static connection between the world frame and the map frame -->
  <link name="map"/>
  <joint name="world_map_joint" type="fixed">
    <origin rpy="0 0 0" xyz="0 0 0"/>
    <parent link="world"/>
    <child link="map"/>
  </joint>
  <!-- the gripper -->
  <joint name="map_gripper_joint" type="fixed">
    <origin rpy="3.14159265359 0 0" xyz="0.0 0.0 0.22"/>
    <parent link="map"/>
    <child link="gripper_mount_link"/>
  </joint>
  <link name="gripper_mount_link">
  </link>
  <!--
  <xacro:barret_hand prefix="right" parent="gripper_mount_link">
    <origin xyz="0.0 0.0 0.0" rpy="0 0 0"/>
  </xacro:barret_hand>
-->
  <!-- the scene -->
  <joint name="map_plane_joint" type="fixed">
    <origin rpy="0 0 0" xyz="0 0 0"/>
    <parent link="map"/>
    <child link="plane"/>
  </joint>
  <link name="plane">
    <inertial>
      <origin xyz="0.00035500 -0.00499005 0.04864979"/>
      <mass value="0.63352875"/>
      <inertia ixx="0.00102103" ixy="0.00000775" ixz="-0.00001230" iyy="0.00080944" iyz="-0.00014417" izz="0.00068788"/>
    </inertial>
    <visual>
      <origin rpy="0 0 0" xyz="0 0 0"/>
      <geometry>
        <mesh filename="package://barrett_hand_sim_dart/meshes/plane.stl"/>
      </geometry>
    </visual>
    <collision>
      <origin rpy="0 0 0" xyz="0 0 0"/>
      <geometry>
        <mesh filename="package://barrett_hand_sim_dart/meshes/plane.stl"/>
      </geometry>
    </collision>
  </link>
  <!-- the graspable object -->
  <joint name="map_graspable_joint" type="floating">
    <origin rpy="0 0 0" xyz="0.0 0.0 0.07"/>
    <parent link="map"/>
    <child link="graspable"/>
  </joint>
  <link name="graspable">
    <inertial>
      <origin xyz="0.00035500 -0.00499005 0.04864979"/>
      <mass value="0.63352875"/>
      <inertia ixx="0.00102103" ixy="0.00000775" ixz="-0.00001230" iyy="0.00080944" iyz="-0.00014417" izz="0.00068788"/>
    </inertial>
    <visual>
      <origin rpy="0 0 0" xyz="0 0 0"/>
      <geometry>
        <mesh filename="package://barrett_hand_sim_dart/meshes/cuboid.stl"/>
      </geometry>
    </visual>
    <collision>
      <origin rpy="0 0 0" xyz="0 0 0"/>
      <geometry>
        <mesh filename="package://barrett_hand_sim_dart/meshes/cuboid.stl"/>
      </geometry>
    </collision>
  </link>
</robot>
