<?xml version="1.0" ?>
<!-- =================================================================================== -->
<!-- |    This document was autogenerated by xacro from /home/dseredyn/ws_velma/underlay/src/barrett_hand_robot/barrett_hand_defs/robots/barrett_hand.urdf.xml | -->
<!-- |    EDITING THIS FILE BY HAND IS NOT RECOMMENDED                                 | -->
<!-- =================================================================================== -->
<robot name="cube5" xmlns:controller="http://playerstage.sourceforge.net/gazebo/xmlschema/#controller" xmlns:geom="http://playerstage.sourceforge.net/gazebo/xmlschema/#geom" xmlns:interface="http://playerstage.sourceforge.net/gazebo/xmlschema/#interface" xmlns:sensor="http://playerstage.sourceforge.net/gazebo/xmlschema/#sensor" xmlns:xacro="http://www.ros.org/wiki/xacro">
  <material name="DarkGrey">
    <color rgba="0.3 0.3 0.3 1.0"/>
  </material>
  <material name="Red">
    <color rgba="0.3 0.3 0.3 1.0"/>
  </material>
  <material name="Black">
    <color rgba="0 0 0 1.0"/>
  </material>
  <material name="Orange">
    <color rgba="1.0 0.487 0 1.0"/>
  </material>
  <material name="Silver">
    <color rgba="1.0 1.0 1.0 1.0"/>
  </material>
  <material name="Grey">
    <color rgba="0.7 0.7 0.7 1.0"/>
  </material>
  <material name="Blue">
    <color rgba="0.0 0.0 0.8 1.0"/>
  </material>
  <material name="HandGray">
    <color rgba="0.953 0.996 0.694 1.0"/>
  </material>
  <material name="SickBlue">
    <color rgba="0.3058 0.5921 0.7294 1.0"/>
  </material>
  <link name="world"/>
  <joint name="arm_world_joint" type="floating">
    <origin rpy="0 0 0" xyz="0 0 0"/>
    <parent link="world"/>
    <child link="cube5"/>
  </joint>
  <link name="cube5">
    <inertial>
      <origin xyz="0.00035500 -0.00499005 0.04864979"/>
      <mass value="0.63352875"/>
      <inertia ixx="0.00102103" ixy="0.00000775" ixz="-0.00001230" iyy="0.00080944" iyz="-0.00014417" izz="0.00068788"/>
    </inertial>
    <visual>
      <origin rpy="0 0 0" xyz="0 0 0"/>
      <geometry>
        <mesh filename="package://barrett_hand_sim_dart/meshes/cuboid.stl"/>
      </geometry>
    </visual>
    <!-- collision mesh used for whole arm motion planning -->
    <!-- collision mesh used for grasp planning -->
    <collision>
      <origin rpy="0 0 0" xyz="0 0 0"/>
      <geometry>
        <mesh filename="package://barrett_hand_sim_dart/meshes/cuboid.stl"/>
      </geometry>
    </collision>
  </link>
  <gazebo reference="cube5">
    <turnGravityOff>true</turnGravityOff>
  </gazebo>
</robot>
